2025-03-06 19:27:34,864 - INFO - Session Supervisor : 72c39750707945e1a74a70fed5d61bd7
2025-03-06 19:29:13,225 - INFO - Session Supervisor : 667bd4be4371440ab4063d5f8192e79e
2025-03-06 19:29:32,815 - INFO - <class 'MESSAGE_QUEUE.MessageQueue'>
2025-03-06 19:30:02,845 - ERROR - Task exception was never retrieved
future: <Task finished name='Task-23' coro=<sessionSupervisorService.ManageRenderingProcess() done, defined at /mnt/c/Users/paart/Paarth Workshop/Startups/Neural Perk/Neuralperk - ProxyUser Integration/Main Server/service_SessionSupervisor/sessionSupervisor.py:534> exception=ConnectionError(MaxRetryError("HTTPConnectionPool(host='127.0.0.1', port=20000): Max retries exceeded with url: /SessionSupervisor/NewSession (Caused by NewConnectionError('<urllib3.connection.HTTPConnection object at 0x7f743c478dd0>: Failed to establish a new connection: [Errno 111] Connection refused'))"))>
Traceback (most recent call last):
  File "/mnt/c/Users/paart/Paarth Workshop/Startups/Neural Perk/Neuralperk - ProxyUser Integration/Main Server/.venv/lib/python3.12/site-packages/urllib3/connection.py", line 198, in _new_conn
    sock = connection.create_connection(
           ^^^^^^^^^^^^^^^^^^^^^^^^^^^^^
  File "/mnt/c/Users/paart/Paarth Workshop/Startups/Neural Perk/Neuralperk - ProxyUser Integration/Main Server/.venv/lib/python3.12/site-packages/urllib3/util/connection.py", line 85, in create_connection
    raise err
  File "/mnt/c/Users/paart/Paarth Workshop/Startups/Neural Perk/Neuralperk - ProxyUser Integration/Main Server/.venv/lib/python3.12/site-packages/urllib3/util/connection.py", line 73, in create_connection
    sock.connect(sa)
ConnectionRefusedError: [Errno 111] Connection refused

The above exception was the direct cause of the following exception:

Traceback (most recent call last):
  File "/mnt/c/Users/paart/Paarth Workshop/Startups/Neural Perk/Neuralperk - ProxyUser Integration/Main Server/.venv/lib/python3.12/site-packages/urllib3/connectionpool.py", line 787, in urlopen
    response = self._make_request(
               ^^^^^^^^^^^^^^^^^^^
  File "/mnt/c/Users/paart/Paarth Workshop/Startups/Neural Perk/Neuralperk - ProxyUser Integration/Main Server/.venv/lib/python3.12/site-packages/urllib3/connectionpool.py", line 493, in _make_request
    conn.request(
  File "/mnt/c/Users/paart/Paarth Workshop/Startups/Neural Perk/Neuralperk - ProxyUser Integration/Main Server/.venv/lib/python3.12/site-packages/urllib3/connection.py", line 445, in request
    self.endheaders()
  File "/usr/lib/python3.12/http/client.py", line 1333, in endheaders
    self._send_output(message_body, encode_chunked=encode_chunked)
  File "/usr/lib/python3.12/http/client.py", line 1093, in _send_output
    self.send(msg)
  File "/usr/lib/python3.12/http/client.py", line 1037, in send
    self.connect()
  File "/mnt/c/Users/paart/Paarth Workshop/Startups/Neural Perk/Neuralperk - ProxyUser Integration/Main Server/.venv/lib/python3.12/site-packages/urllib3/connection.py", line 276, in connect
    self.sock = self._new_conn()
                ^^^^^^^^^^^^^^^^
  File "/mnt/c/Users/paart/Paarth Workshop/Startups/Neural Perk/Neuralperk - ProxyUser Integration/Main Server/.venv/lib/python3.12/site-packages/urllib3/connection.py", line 213, in _new_conn
    raise NewConnectionError(
urllib3.exceptions.NewConnectionError: <urllib3.connection.HTTPConnection object at 0x7f743c478dd0>: Failed to establish a new connection: [Errno 111] Connection refused

The above exception was the direct cause of the following exception:

Traceback (most recent call last):
  File "/mnt/c/Users/paart/Paarth Workshop/Startups/Neural Perk/Neuralperk - ProxyUser Integration/Main Server/.venv/lib/python3.12/site-packages/requests/adapters.py", line 667, in send
    resp = conn.urlopen(
           ^^^^^^^^^^^^^
  File "/mnt/c/Users/paart/Paarth Workshop/Startups/Neural Perk/Neuralperk - ProxyUser Integration/Main Server/.venv/lib/python3.12/site-packages/urllib3/connectionpool.py", line 841, in urlopen
    retries = retries.increment(
              ^^^^^^^^^^^^^^^^^^
  File "/mnt/c/Users/paart/Paarth Workshop/Startups/Neural Perk/Neuralperk - ProxyUser Integration/Main Server/.venv/lib/python3.12/site-packages/urllib3/util/retry.py", line 519, in increment
    raise MaxRetryError(_pool, url, reason) from reason  # type: ignore[arg-type]
    ^^^^^^^^^^^^^^^^^^^^^^^^^^^^^^^^^^^^^^^^^^^^^^^^^^^
urllib3.exceptions.MaxRetryError: HTTPConnectionPool(host='127.0.0.1', port=20000): Max retries exceeded with url: /SessionSupervisor/NewSession (Caused by NewConnectionError('<urllib3.connection.HTTPConnection object at 0x7f743c478dd0>: Failed to establish a new connection: [Errno 111] Connection refused'))

During handling of the above exception, another exception occurred:

Traceback (most recent call last):
  File "/mnt/c/Users/paart/Paarth Workshop/Startups/Neural Perk/Neuralperk - ProxyUser Integration/Main Server/service_SessionSupervisor/sessionSupervisor.py", line 536, in ManageRenderingProcess
    await self.supervisor.RenderingProcessInititalSetup()
  File "/mnt/c/Users/paart/Paarth Workshop/Startups/Neural Perk/Neuralperk - ProxyUser Integration/Main Server/service_SessionSupervisor/sessionSupervisor.py", line 484, in RenderingProcessInititalSetup
    response = requests.post(f"http://{userManagerServiceURL}/SessionSupervisor/NewSession" , json=messageToSend, headers=headersToSend)
               ^^^^^^^^^^^^^^^^^^^^^^^^^^^^^^^^^^^^^^^^^^^^^^^^^^^^^^^^^^^^^^^^^^^^^^^^^^^^^^^^^^^^^^^^^^^^^^^^^^^^^^^^^^^^^^^^^^^^^^^^^
  File "/mnt/c/Users/paart/Paarth Workshop/Startups/Neural Perk/Neuralperk - ProxyUser Integration/Main Server/.venv/lib/python3.12/site-packages/requests/api.py", line 115, in post
    return request("post", url, data=data, json=json, **kwargs)
           ^^^^^^^^^^^^^^^^^^^^^^^^^^^^^^^^^^^^^^^^^^^^^^^^^^^^
  File "/mnt/c/Users/paart/Paarth Workshop/Startups/Neural Perk/Neuralperk - ProxyUser Integration/Main Server/.venv/lib/python3.12/site-packages/requests/api.py", line 59, in request
    return session.request(method=method, url=url, **kwargs)
           ^^^^^^^^^^^^^^^^^^^^^^^^^^^^^^^^^^^^^^^^^^^^^^^^^
  File "/mnt/c/Users/paart/Paarth Workshop/Startups/Neural Perk/Neuralperk - ProxyUser Integration/Main Server/.venv/lib/python3.12/site-packages/requests/sessions.py", line 589, in request
    resp = self.send(prep, **send_kwargs)
           ^^^^^^^^^^^^^^^^^^^^^^^^^^^^^^
  File "/mnt/c/Users/paart/Paarth Workshop/Startups/Neural Perk/Neuralperk - ProxyUser Integration/Main Server/.venv/lib/python3.12/site-packages/requests/sessions.py", line 703, in send
    r = adapter.send(request, **kwargs)
        ^^^^^^^^^^^^^^^^^^^^^^^^^^^^^^^
  File "/mnt/c/Users/paart/Paarth Workshop/Startups/Neural Perk/Neuralperk - ProxyUser Integration/Main Server/.venv/lib/python3.12/site-packages/requests/adapters.py", line 700, in send
    raise ConnectionError(e, request=request)
requests.exceptions.ConnectionError: HTTPConnectionPool(host='127.0.0.1', port=20000): Max retries exceeded with url: /SessionSupervisor/NewSession (Caused by NewConnectionError('<urllib3.connection.HTTPConnection object at 0x7f743c478dd0>: Failed to establish a new connection: [Errno 111] Connection refused'))
