INFO:     Started server process [88584]
INFO:     Waiting for application startup.
INFO:     Application startup complete.
INFO:     Uvicorn running on http://0.0.0.0:5937 (Press CTRL+C to quit)
INFO:     Shutting down
INFO:     Waiting for application shutdown.
INFO:     Application shutdown complete.
INFO:     Finished server process [88584]
Traceback (most recent call last):
  File "/usr/lib/python3.12/asyncio/runners.py", line 118, in run
    return self._loop.run_until_complete(task)
           ^^^^^^^^^^^^^^^^^^^^^^^^^^^^^^^^^^^
  File "/usr/lib/python3.12/asyncio/base_events.py", line 691, in run_until_complete
    return future.result()
           ^^^^^^^^^^^^^^^
asyncio.exceptions.CancelledError

During handling of the above exception, another exception occurred:

Traceback (most recent call last):
  File "/home/paarth/Neuralperk_ProxyUser_MainServer/service_AuthService/auth-service.py", line 306, in <module>
    asyncio.run(start_service())
  File "/usr/lib/python3.12/asyncio/runners.py", line 195, in run
    return runner.run(main)
           ^^^^^^^^^^^^^^^^
  File "/usr/lib/python3.12/asyncio/runners.py", line 123, in run
    raise KeyboardInterrupt()
KeyboardInterrupt
INFO:     Started server process [88777]
INFO:     Waiting for application startup.
INFO:     Application startup complete.
INFO:     Uvicorn running on http://0.0.0.0:5937 (Press CTRL+C to quit)
INFO:     Shutting down
INFO:     Waiting for application shutdown.
INFO:     Application shutdown complete.
INFO:     Finished server process [88777]
Traceback (most recent call last):
  File "/usr/lib/python3.12/asyncio/runners.py", line 118, in run
    return self._loop.run_until_complete(task)
           ^^^^^^^^^^^^^^^^^^^^^^^^^^^^^^^^^^^
  File "/usr/lib/python3.12/asyncio/base_events.py", line 691, in run_until_complete
    return future.result()
           ^^^^^^^^^^^^^^^
asyncio.exceptions.CancelledError

During handling of the above exception, another exception occurred:

Traceback (most recent call last):
  File "/home/paarth/Neuralperk_ProxyUser_MainServer/service_AuthService/auth-service.py", line 306, in <module>
    asyncio.run(start_service())
  File "/usr/lib/python3.12/asyncio/runners.py", line 195, in run
    return runner.run(main)
           ^^^^^^^^^^^^^^^^
  File "/usr/lib/python3.12/asyncio/runners.py", line 123, in run
    raise KeyboardInterrupt()
KeyboardInterrupt
INFO:     Started server process [88881]
INFO:     Waiting for application startup.
INFO:     Application startup complete.
INFO:     Uvicorn running on http://0.0.0.0:5937 (Press CTRL+C to quit)
INFO:     Shutting down
INFO:     Waiting for application shutdown.
INFO:     Application shutdown complete.
INFO:     Finished server process [88881]
Traceback (most recent call last):
  File "/usr/lib/python3.12/asyncio/runners.py", line 118, in run
    return self._loop.run_until_complete(task)
           ^^^^^^^^^^^^^^^^^^^^^^^^^^^^^^^^^^^
  File "/usr/lib/python3.12/asyncio/base_events.py", line 691, in run_until_complete
    return future.result()
           ^^^^^^^^^^^^^^^
asyncio.exceptions.CancelledError

During handling of the above exception, another exception occurred:

Traceback (most recent call last):
  File "/home/paarth/Neuralperk_ProxyUser_MainServer/service_AuthService/auth-service.py", line 306, in <module>
    asyncio.run(start_service())
  File "/usr/lib/python3.12/asyncio/runners.py", line 195, in run
    return runner.run(main)
           ^^^^^^^^^^^^^^^^
  File "/usr/lib/python3.12/asyncio/runners.py", line 123, in run
    raise KeyboardInterrupt()
KeyboardInterrupt
INFO:     Started server process [88965]
INFO:     Waiting for application startup.
INFO:     Application startup complete.
INFO:     Uvicorn running on http://0.0.0.0:5937 (Press CTRL+C to quit)
INFO:     Shutting down
INFO:     Waiting for application shutdown.
INFO:     Application shutdown complete.
INFO:     Finished server process [88965]
Traceback (most recent call last):
  File "/usr/lib/python3.12/asyncio/runners.py", line 118, in run
    return self._loop.run_until_complete(task)
           ^^^^^^^^^^^^^^^^^^^^^^^^^^^^^^^^^^^
  File "/usr/lib/python3.12/asyncio/base_events.py", line 691, in run_until_complete
    return future.result()
           ^^^^^^^^^^^^^^^
asyncio.exceptions.CancelledError

During handling of the above exception, another exception occurred:

Traceback (most recent call last):
  File "/home/paarth/Neuralperk_ProxyUser_MainServer/service_AuthService/auth-service.py", line 306, in <module>
    asyncio.run(start_service())
  File "/usr/lib/python3.12/asyncio/runners.py", line 195, in run
    return runner.run(main)
           ^^^^^^^^^^^^^^^^
  File "/usr/lib/python3.12/asyncio/runners.py", line 123, in run
    raise KeyboardInterrupt()
KeyboardInterrupt
INFO:     Started server process [89135]
INFO:     Waiting for application startup.
INFO:     Application startup complete.
ERROR:    [Errno 98] Address already in use
INFO:     Waiting for application shutdown.
INFO:     Application shutdown complete.
INFO:     Started server process [89149]
INFO:     Waiting for application startup.
INFO:     Application startup complete.
ERROR:    [Errno 98] error while attempting to bind on address ('0.0.0.0', 5937): [errno 98] address already in use
INFO:     Waiting for application shutdown.
INFO:     Application shutdown complete.
INFO:     Started server process [89160]
INFO:     Waiting for application startup.
INFO:     Application startup complete.
ERROR:    [Errno 98] error while attempting to bind on address ('0.0.0.0', 5937): [errno 98] address already in use
INFO:     Waiting for application shutdown.
INFO:     Application shutdown complete.
INFO:     Started server process [89161]
INFO:     Waiting for application startup.
INFO:     Application startup complete.
ERROR:    [Errno 98] error while attempting to bind on address ('0.0.0.0', 5937): [errno 98] address already in use
INFO:     Waiting for application shutdown.
INFO:     Application shutdown complete.
INFO:     Started server process [89166]
INFO:     Waiting for application startup.
INFO:     Application startup complete.
ERROR:    [Errno 98] error while attempting to bind on address ('0.0.0.0', 5937): [errno 98] address already in use
INFO:     Waiting for application shutdown.
INFO:     Application shutdown complete.
INFO:     Started server process [89168]
INFO:     Waiting for application startup.
INFO:     Application startup complete.
ERROR:    [Errno 98] error while attempting to bind on address ('0.0.0.0', 5937): [errno 98] address already in use
INFO:     Waiting for application shutdown.
INFO:     Application shutdown complete.
INFO:     Started server process [89179]
INFO:     Waiting for application startup.
INFO:     Application startup complete.
ERROR:    [Errno 98] error while attempting to bind on address ('0.0.0.0', 5937): [errno 98] address already in use
INFO:     Waiting for application shutdown.
INFO:     Application shutdown complete.
INFO:     Started server process [89180]
INFO:     Waiting for application startup.
INFO:     Application startup complete.
ERROR:    [Errno 98] error while attempting to bind on address ('0.0.0.0', 5937): [errno 98] address already in use
INFO:     Waiting for application shutdown.
INFO:     Application shutdown complete.
INFO:     Started server process [89185]
INFO:     Waiting for application startup.
INFO:     Application startup complete.
ERROR:    [Errno 98] error while attempting to bind on address ('0.0.0.0', 5937): [errno 98] address already in use
INFO:     Waiting for application shutdown.
INFO:     Application shutdown complete.
INFO:     Started server process [89187]
INFO:     Waiting for application startup.
INFO:     Application startup complete.
ERROR:    [Errno 98] error while attempting to bind on address ('0.0.0.0', 5937): [errno 98] address already in use
INFO:     Waiting for application shutdown.
INFO:     Application shutdown complete.
INFO:     Started server process [89189]
INFO:     Waiting for application startup.
INFO:     Application startup complete.
ERROR:    [Errno 98] error while attempting to bind on address ('0.0.0.0', 5937): [errno 98] address already in use
INFO:     Waiting for application shutdown.
INFO:     Application shutdown complete.
INFO:     Started server process [89190]
INFO:     Waiting for application startup.
INFO:     Application startup complete.
ERROR:    [Errno 98] error while attempting to bind on address ('0.0.0.0', 5937): [errno 98] address already in use
INFO:     Waiting for application shutdown.
INFO:     Application shutdown complete.
INFO:     Started server process [89192]
INFO:     Waiting for application startup.
INFO:     Application startup complete.
ERROR:    [Errno 98] error while attempting to bind on address ('0.0.0.0', 5937): [errno 98] address already in use
INFO:     Waiting for application shutdown.
INFO:     Application shutdown complete.
INFO:     Started server process [89194]
INFO:     Waiting for application startup.
INFO:     Application startup complete.
ERROR:    [Errno 98] error while attempting to bind on address ('0.0.0.0', 5937): [errno 98] address already in use
INFO:     Waiting for application shutdown.
INFO:     Application shutdown complete.
INFO:     Started server process [89196]
INFO:     Waiting for application startup.
INFO:     Application startup complete.
ERROR:    [Errno 98] error while attempting to bind on address ('0.0.0.0', 5937): [errno 98] address already in use
INFO:     Waiting for application shutdown.
INFO:     Application shutdown complete.
INFO:     Started server process [89213]
INFO:     Waiting for application startup.
INFO:     Application startup complete.
ERROR:    [Errno 98] error while attempting to bind on address ('0.0.0.0', 5937): [errno 98] address already in use
INFO:     Waiting for application shutdown.
INFO:     Application shutdown complete.
INFO:     Started server process [89261]
INFO:     Waiting for application startup.
INFO:     Application startup complete.
INFO:     Uvicorn running on http://0.0.0.0:5937 (Press CTRL+C to quit)
INFO:     Shutting down
INFO:     Waiting for application shutdown.
INFO:     Application shutdown complete.
INFO:     Finished server process [89261]
Traceback (most recent call last):
  File "/usr/lib/python3.12/asyncio/runners.py", line 118, in run
    return self._loop.run_until_complete(task)
           ^^^^^^^^^^^^^^^^^^^^^^^^^^^^^^^^^^^
  File "/usr/lib/python3.12/asyncio/base_events.py", line 691, in run_until_complete
    return future.result()
           ^^^^^^^^^^^^^^^
asyncio.exceptions.CancelledError

During handling of the above exception, another exception occurred:

Traceback (most recent call last):
  File "/home/paarth/Neuralperk_ProxyUser_MainServer/service_AuthService/auth-service.py", line 306, in <module>
    asyncio.run(start_service())
  File "/usr/lib/python3.12/asyncio/runners.py", line 195, in run
    return runner.run(main)
           ^^^^^^^^^^^^^^^^
  File "/usr/lib/python3.12/asyncio/runners.py", line 123, in run
    raise KeyboardInterrupt()
KeyboardInterrupt
INFO:     Started server process [89359]
INFO:     Waiting for application startup.
INFO:     Application startup complete.
INFO:     Uvicorn running on http://0.0.0.0:5937 (Press CTRL+C to quit)
INFO:     Shutting down
INFO:     Waiting for application shutdown.
INFO:     Application shutdown complete.
INFO:     Finished server process [89359]
Traceback (most recent call last):
  File "/usr/lib/python3.12/asyncio/runners.py", line 118, in run
    return self._loop.run_until_complete(task)
           ^^^^^^^^^^^^^^^^^^^^^^^^^^^^^^^^^^^
  File "/usr/lib/python3.12/asyncio/base_events.py", line 691, in run_until_complete
    return future.result()
           ^^^^^^^^^^^^^^^
asyncio.exceptions.CancelledError

During handling of the above exception, another exception occurred:

Traceback (most recent call last):
  File "/home/paarth/Neuralperk_ProxyUser_MainServer/service_AuthService/auth-service.py", line 306, in <module>
    asyncio.run(start_service())
  File "/usr/lib/python3.12/asyncio/runners.py", line 195, in run
    return runner.run(main)
           ^^^^^^^^^^^^^^^^
  File "/usr/lib/python3.12/asyncio/runners.py", line 123, in run
    raise KeyboardInterrupt()
KeyboardInterrupt
INFO:     Started server process [89542]
INFO:     Waiting for application startup.
INFO:     Application startup complete.
ERROR:    [Errno 98] error while attempting to bind on address ('0.0.0.0', 5937): [errno 98] address already in use
INFO:     Waiting for application shutdown.
INFO:     Application shutdown complete.
INFO:     Started server process [89550]
INFO:     Waiting for application startup.
INFO:     Application startup complete.
ERROR:    [Errno 98] error while attempting to bind on address ('0.0.0.0', 5937): [errno 98] address already in use
INFO:     Waiting for application shutdown.
INFO:     Application shutdown complete.
INFO:     Started server process [89552]
INFO:     Waiting for application startup.
INFO:     Application startup complete.
ERROR:    [Errno 98] error while attempting to bind on address ('0.0.0.0', 5937): [errno 98] address already in use
INFO:     Waiting for application shutdown.
INFO:     Application shutdown complete.
INFO:     Started server process [89557]
INFO:     Waiting for application startup.
INFO:     Application startup complete.
ERROR:    [Errno 98] error while attempting to bind on address ('0.0.0.0', 5937): [errno 98] address already in use
INFO:     Waiting for application shutdown.
INFO:     Application shutdown complete.
INFO:     Started server process [89571]
INFO:     Waiting for application startup.
INFO:     Application startup complete.
ERROR:    [Errno 98] error while attempting to bind on address ('0.0.0.0', 5937): [errno 98] address already in use
INFO:     Waiting for application shutdown.
INFO:     Application shutdown complete.
INFO:     Started server process [89574]
INFO:     Waiting for application startup.
INFO:     Application startup complete.
ERROR:    [Errno 98] error while attempting to bind on address ('0.0.0.0', 5937): [errno 98] address already in use
INFO:     Waiting for application shutdown.
INFO:     Application shutdown complete.
INFO:     Started server process [89577]
INFO:     Waiting for application startup.
INFO:     Application startup complete.
ERROR:    [Errno 98] error while attempting to bind on address ('0.0.0.0', 5937): [errno 98] address already in use
INFO:     Waiting for application shutdown.
INFO:     Application shutdown complete.
INFO:     Started server process [89582]
INFO:     Waiting for application startup.
INFO:     Application startup complete.
ERROR:    [Errno 98] error while attempting to bind on address ('0.0.0.0', 5937): [errno 98] address already in use
INFO:     Waiting for application shutdown.
INFO:     Application shutdown complete.
INFO:     Started server process [89584]
INFO:     Waiting for application startup.
INFO:     Application startup complete.
ERROR:    [Errno 98] error while attempting to bind on address ('0.0.0.0', 5937): [errno 98] address already in use
INFO:     Waiting for application shutdown.
INFO:     Application shutdown complete.
INFO:     Started server process [89585]
INFO:     Waiting for application startup.
INFO:     Application startup complete.
ERROR:    [Errno 98] error while attempting to bind on address ('0.0.0.0', 5937): [errno 98] address already in use
INFO:     Waiting for application shutdown.
INFO:     Application shutdown complete.
INFO:     Started server process [89588]
INFO:     Waiting for application startup.
INFO:     Application startup complete.
ERROR:    [Errno 98] error while attempting to bind on address ('0.0.0.0', 5937): [errno 98] address already in use
INFO:     Waiting for application shutdown.
INFO:     Application shutdown complete.
INFO:     Started server process [89590]
INFO:     Waiting for application startup.
INFO:     Application startup complete.
ERROR:    [Errno 98] error while attempting to bind on address ('0.0.0.0', 5937): [errno 98] address already in use
INFO:     Waiting for application shutdown.
INFO:     Application shutdown complete.
INFO:     Started server process [89592]
INFO:     Waiting for application startup.
INFO:     Application startup complete.
ERROR:    [Errno 98] error while attempting to bind on address ('0.0.0.0', 5937): [errno 98] address already in use
INFO:     Waiting for application shutdown.
INFO:     Application shutdown complete.
INFO:     Started server process [89593]
INFO:     Waiting for application startup.
INFO:     Application startup complete.
ERROR:    [Errno 98] error while attempting to bind on address ('0.0.0.0', 5937): [errno 98] address already in use
INFO:     Waiting for application shutdown.
INFO:     Application shutdown complete.
INFO:     Started server process [89595]
INFO:     Waiting for application startup.
INFO:     Application startup complete.
ERROR:    [Errno 98] error while attempting to bind on address ('0.0.0.0', 5937): [errno 98] address already in use
INFO:     Waiting for application shutdown.
INFO:     Application shutdown complete.
INFO:     Started server process [89597]
INFO:     Waiting for application startup.
INFO:     Application startup complete.
ERROR:    [Errno 98] error while attempting to bind on address ('0.0.0.0', 5937): [errno 98] address already in use
INFO:     Waiting for application shutdown.
INFO:     Application shutdown complete.
INFO:     Started server process [89735]
INFO:     Waiting for application startup.
INFO:     Application startup complete.
ERROR:    [Errno 98] error while attempting to bind on address ('0.0.0.0', 5937): [errno 98] address already in use
INFO:     Waiting for application shutdown.
INFO:     Application shutdown complete.
INFO:     Started server process [89743]
INFO:     Waiting for application startup.
INFO:     Application startup complete.
ERROR:    [Errno 98] error while attempting to bind on address ('0.0.0.0', 5937): [errno 98] address already in use
INFO:     Waiting for application shutdown.
INFO:     Application shutdown complete.
INFO:     Started server process [89745]
INFO:     Waiting for application startup.
INFO:     Application startup complete.
ERROR:    [Errno 98] error while attempting to bind on address ('0.0.0.0', 5937): [errno 98] address already in use
INFO:     Waiting for application shutdown.
INFO:     Application shutdown complete.
INFO:     Started server process [89747]
INFO:     Waiting for application startup.
INFO:     Application startup complete.
ERROR:    [Errno 98] error while attempting to bind on address ('0.0.0.0', 5937): [errno 98] address already in use
INFO:     Waiting for application shutdown.
INFO:     Application shutdown complete.
INFO:     Started server process [89748]
INFO:     Waiting for application startup.
INFO:     Application startup complete.
ERROR:    [Errno 98] error while attempting to bind on address ('0.0.0.0', 5937): [errno 98] address already in use
INFO:     Waiting for application shutdown.
INFO:     Application shutdown complete.
INFO:     Started server process [89750]
INFO:     Waiting for application startup.
INFO:     Application startup complete.
ERROR:    [Errno 98] error while attempting to bind on address ('0.0.0.0', 5937): [errno 98] address already in use
INFO:     Waiting for application shutdown.
INFO:     Application shutdown complete.
INFO:     Started server process [89752]
INFO:     Waiting for application startup.
INFO:     Application startup complete.
ERROR:    [Errno 98] error while attempting to bind on address ('0.0.0.0', 5937): [errno 98] address already in use
INFO:     Waiting for application shutdown.
INFO:     Application shutdown complete.
INFO:     Started server process [89754]
INFO:     Waiting for application startup.
INFO:     Application startup complete.
ERROR:    [Errno 98] error while attempting to bind on address ('0.0.0.0', 5937): [errno 98] address already in use
INFO:     Waiting for application shutdown.
INFO:     Application shutdown complete.
INFO:     Started server process [89755]
INFO:     Waiting for application startup.
INFO:     Application startup complete.
ERROR:    [Errno 98] error while attempting to bind on address ('0.0.0.0', 5937): [errno 98] address already in use
INFO:     Waiting for application shutdown.
INFO:     Application shutdown complete.
INFO:     Started server process [89757]
INFO:     Waiting for application startup.
INFO:     Application startup complete.
ERROR:    [Errno 98] error while attempting to bind on address ('0.0.0.0', 5937): [errno 98] address already in use
INFO:     Waiting for application shutdown.
INFO:     Application shutdown complete.
INFO:     Started server process [89759]
INFO:     Waiting for application startup.
INFO:     Application startup complete.
ERROR:    [Errno 98] error while attempting to bind on address ('0.0.0.0', 5937): [errno 98] address already in use
INFO:     Waiting for application shutdown.
INFO:     Application shutdown complete.
INFO:     Started server process [89760]
INFO:     Waiting for application startup.
INFO:     Application startup complete.
ERROR:    [Errno 98] error while attempting to bind on address ('0.0.0.0', 5937): [errno 98] address already in use
INFO:     Waiting for application shutdown.
INFO:     Application shutdown complete.
INFO:     Started server process [89762]
INFO:     Waiting for application startup.
INFO:     Application startup complete.
ERROR:    [Errno 98] error while attempting to bind on address ('0.0.0.0', 5937): [errno 98] address already in use
INFO:     Waiting for application shutdown.
INFO:     Application shutdown complete.
INFO:     Started server process [89776]
INFO:     Waiting for application startup.
INFO:     Application startup complete.
ERROR:    [Errno 98] error while attempting to bind on address ('0.0.0.0', 5937): [errno 98] address already in use
INFO:     Waiting for application shutdown.
INFO:     Application shutdown complete.
INFO:     Started server process [89778]
INFO:     Waiting for application startup.
INFO:     Application startup complete.
ERROR:    [Errno 98] error while attempting to bind on address ('0.0.0.0', 5937): [errno 98] address already in use
INFO:     Waiting for application shutdown.
INFO:     Application shutdown complete.
INFO:     Started server process [89780]
INFO:     Waiting for application startup.
INFO:     Application startup complete.
ERROR:    [Errno 98] error while attempting to bind on address ('0.0.0.0', 5937): [errno 98] address already in use
INFO:     Waiting for application shutdown.
INFO:     Application shutdown complete.
INFO:     Started server process [90366]
INFO:     Waiting for application startup.
INFO:     Application startup complete.
INFO:     Uvicorn running on http://0.0.0.0:10000 (Press CTRL+C to quit)
INFO:     Shutting down
INFO:     Waiting for application shutdown.
INFO:     Application shutdown complete.
INFO:     Finished server process [90366]
Traceback (most recent call last):
  File "/usr/lib/python3.12/asyncio/runners.py", line 118, in run
    return self._loop.run_until_complete(task)
           ^^^^^^^^^^^^^^^^^^^^^^^^^^^^^^^^^^^
  File "/usr/lib/python3.12/asyncio/base_events.py", line 691, in run_until_complete
    return future.result()
           ^^^^^^^^^^^^^^^
asyncio.exceptions.CancelledError

During handling of the above exception, another exception occurred:

Traceback (most recent call last):
  File "/home/paarth/Neuralperk_ProxyUser_MainServer/service_AuthService/auth-service.py", line 306, in <module>
    asyncio.run(start_service())
  File "/usr/lib/python3.12/asyncio/runners.py", line 195, in run
    return runner.run(main)
           ^^^^^^^^^^^^^^^^
  File "/usr/lib/python3.12/asyncio/runners.py", line 123, in run
    raise KeyboardInterrupt()
KeyboardInterrupt
INFO:     Started server process [90904]
INFO:     Waiting for application startup.
INFO:     Application startup complete.
INFO:     Uvicorn running on http://0.0.0.0:10000 (Press CTRL+C to quit)
INFO:     Shutting down
INFO:     Waiting for application shutdown.
INFO:     Application shutdown complete.
INFO:     Finished server process [90904]
Traceback (most recent call last):
  File "/usr/lib/python3.12/asyncio/runners.py", line 118, in run
    return self._loop.run_until_complete(task)
           ^^^^^^^^^^^^^^^^^^^^^^^^^^^^^^^^^^^
  File "/usr/lib/python3.12/asyncio/base_events.py", line 691, in run_until_complete
    return future.result()
           ^^^^^^^^^^^^^^^
asyncio.exceptions.CancelledError

During handling of the above exception, another exception occurred:

Traceback (most recent call last):
  File "/home/paarth/Neuralperk_ProxyUser_MainServer/service_AuthService/auth-service.py", line 306, in <module>
    asyncio.run(start_service())
  File "/usr/lib/python3.12/asyncio/runners.py", line 195, in run
    return runner.run(main)
           ^^^^^^^^^^^^^^^^
  File "/usr/lib/python3.12/asyncio/runners.py", line 123, in run
    raise KeyboardInterrupt()
KeyboardInterrupt
INFO:     Started server process [92171]
INFO:     Waiting for application startup.
INFO:     Application startup complete.
INFO:     Uvicorn running on http://0.0.0.0:10000 (Press CTRL+C to quit)
INFO:     Shutting down
INFO:     Waiting for application shutdown.
INFO:     Application shutdown complete.
INFO:     Finished server process [92171]
Traceback (most recent call last):
  File "/usr/lib/python3.12/asyncio/runners.py", line 118, in run
    return self._loop.run_until_complete(task)
           ^^^^^^^^^^^^^^^^^^^^^^^^^^^^^^^^^^^
  File "/usr/lib/python3.12/asyncio/base_events.py", line 691, in run_until_complete
    return future.result()
           ^^^^^^^^^^^^^^^
asyncio.exceptions.CancelledError

During handling of the above exception, another exception occurred:

Traceback (most recent call last):
  File "/home/paarth/Neuralperk_ProxyUser_MainServer/service_AuthService/auth-service.py", line 306, in <module>
    asyncio.run(start_service())
  File "/usr/lib/python3.12/asyncio/runners.py", line 195, in run
    return runner.run(main)
           ^^^^^^^^^^^^^^^^
  File "/usr/lib/python3.12/asyncio/runners.py", line 123, in run
    raise KeyboardInterrupt()
KeyboardInterrupt
INFO:     Started server process [92485]
INFO:     Waiting for application startup.
INFO:     Application startup complete.
INFO:     Uvicorn running on http://0.0.0.0:10000 (Press CTRL+C to quit)
INFO:     Shutting down
INFO:     Waiting for application shutdown.
INFO:     Application shutdown complete.
INFO:     Finished server process [92485]
Traceback (most recent call last):
  File "/usr/lib/python3.12/asyncio/runners.py", line 118, in run
    return self._loop.run_until_complete(task)
           ^^^^^^^^^^^^^^^^^^^^^^^^^^^^^^^^^^^
  File "/usr/lib/python3.12/asyncio/base_events.py", line 691, in run_until_complete
    return future.result()
           ^^^^^^^^^^^^^^^
asyncio.exceptions.CancelledError

During handling of the above exception, another exception occurred:

Traceback (most recent call last):
  File "/home/paarth/Neuralperk_ProxyUser_MainServer/service_AuthService/auth-service.py", line 306, in <module>
    asyncio.run(start_service())
  File "/usr/lib/python3.12/asyncio/runners.py", line 195, in run
    return runner.run(main)
           ^^^^^^^^^^^^^^^^
  File "/usr/lib/python3.12/asyncio/runners.py", line 123, in run
    raise KeyboardInterrupt()
KeyboardInterrupt
INFO:     Started server process [92798]
INFO:     Waiting for application startup.
INFO:     Application startup complete.
INFO:     Uvicorn running on http://0.0.0.0:10000 (Press CTRL+C to quit)
INFO:     Shutting down
INFO:     Waiting for application shutdown.
INFO:     Application shutdown complete.
INFO:     Finished server process [92798]
Traceback (most recent call last):
  File "/usr/lib/python3.12/asyncio/runners.py", line 118, in run
    return self._loop.run_until_complete(task)
           ^^^^^^^^^^^^^^^^^^^^^^^^^^^^^^^^^^^
  File "/usr/lib/python3.12/asyncio/base_events.py", line 691, in run_until_complete
    return future.result()
           ^^^^^^^^^^^^^^^
asyncio.exceptions.CancelledError

During handling of the above exception, another exception occurred:

Traceback (most recent call last):
  File "/home/paarth/Neuralperk_ProxyUser_MainServer/service_AuthService/auth-service.py", line 306, in <module>
    asyncio.run(start_service())
  File "/usr/lib/python3.12/asyncio/runners.py", line 195, in run
    return runner.run(main)
           ^^^^^^^^^^^^^^^^
  File "/usr/lib/python3.12/asyncio/runners.py", line 123, in run
    raise KeyboardInterrupt()
KeyboardInterrupt
INFO:     Started server process [92871]
INFO:     Waiting for application startup.
INFO:     Application startup complete.
INFO:     Uvicorn running on http://0.0.0.0:10000 (Press CTRL+C to quit)
INFO:     Shutting down
INFO:     Waiting for application shutdown.
INFO:     Application shutdown complete.
INFO:     Finished server process [92871]
Traceback (most recent call last):
  File "/usr/lib/python3.12/asyncio/runners.py", line 118, in run
    return self._loop.run_until_complete(task)
           ^^^^^^^^^^^^^^^^^^^^^^^^^^^^^^^^^^^
  File "/usr/lib/python3.12/asyncio/base_events.py", line 691, in run_until_complete
    return future.result()
           ^^^^^^^^^^^^^^^
asyncio.exceptions.CancelledError

During handling of the above exception, another exception occurred:

Traceback (most recent call last):
  File "/home/paarth/Neuralperk_ProxyUser_MainServer/service_AuthService/auth-service.py", line 306, in <module>
    asyncio.run(start_service())
  File "/usr/lib/python3.12/asyncio/runners.py", line 195, in run
    return runner.run(main)
           ^^^^^^^^^^^^^^^^
  File "/usr/lib/python3.12/asyncio/runners.py", line 123, in run
    raise KeyboardInterrupt()
KeyboardInterrupt
INFO:     Started server process [93010]
INFO:     Waiting for application startup.
INFO:     Application startup complete.
INFO:     Uvicorn running on http://0.0.0.0:10000 (Press CTRL+C to quit)
INFO:     Shutting down
INFO:     Waiting for application shutdown.
INFO:     Application shutdown complete.
INFO:     Finished server process [93010]
Traceback (most recent call last):
  File "/usr/lib/python3.12/asyncio/runners.py", line 118, in run
    return self._loop.run_until_complete(task)
           ^^^^^^^^^^^^^^^^^^^^^^^^^^^^^^^^^^^
  File "/usr/lib/python3.12/asyncio/base_events.py", line 691, in run_until_complete
    return future.result()
           ^^^^^^^^^^^^^^^
asyncio.exceptions.CancelledError

During handling of the above exception, another exception occurred:

Traceback (most recent call last):
  File "/home/paarth/Neuralperk_ProxyUser_MainServer/service_AuthService/auth-service.py", line 306, in <module>
    asyncio.run(start_service())
  File "/usr/lib/python3.12/asyncio/runners.py", line 195, in run
    return runner.run(main)
           ^^^^^^^^^^^^^^^^
  File "/usr/lib/python3.12/asyncio/runners.py", line 123, in run
    raise KeyboardInterrupt()
KeyboardInterrupt
INFO:     Started server process [93172]
INFO:     Waiting for application startup.
INFO:     Application startup complete.
INFO:     Uvicorn running on http://0.0.0.0:10000 (Press CTRL+C to quit)
INFO:     Shutting down
INFO:     Waiting for application shutdown.
INFO:     Application shutdown complete.
INFO:     Finished server process [93172]
Traceback (most recent call last):
  File "/usr/lib/python3.12/asyncio/runners.py", line 118, in run
    return self._loop.run_until_complete(task)
           ^^^^^^^^^^^^^^^^^^^^^^^^^^^^^^^^^^^
  File "/usr/lib/python3.12/asyncio/base_events.py", line 691, in run_until_complete
    return future.result()
           ^^^^^^^^^^^^^^^
asyncio.exceptions.CancelledError

During handling of the above exception, another exception occurred:

Traceback (most recent call last):
  File "/home/paarth/Neuralperk_ProxyUser_MainServer/service_AuthService/auth-service.py", line 306, in <module>
    asyncio.run(start_service())
  File "/usr/lib/python3.12/asyncio/runners.py", line 195, in run
    return runner.run(main)
           ^^^^^^^^^^^^^^^^
  File "/usr/lib/python3.12/asyncio/runners.py", line 123, in run
    raise KeyboardInterrupt()
KeyboardInterrupt
INFO:     Started server process [94287]
INFO:     Waiting for application startup.
INFO:     Application startup complete.
INFO:     Uvicorn running on http://0.0.0.0:10000 (Press CTRL+C to quit)
INFO:     Shutting down
INFO:     Waiting for application shutdown.
INFO:     Application shutdown complete.
INFO:     Finished server process [94287]
Traceback (most recent call last):
  File "/usr/lib/python3.12/asyncio/runners.py", line 118, in run
    return self._loop.run_until_complete(task)
           ^^^^^^^^^^^^^^^^^^^^^^^^^^^^^^^^^^^
  File "/usr/lib/python3.12/asyncio/base_events.py", line 691, in run_until_complete
    return future.result()
           ^^^^^^^^^^^^^^^
asyncio.exceptions.CancelledError

During handling of the above exception, another exception occurred:

Traceback (most recent call last):
  File "/home/paarth/Neuralperk_ProxyUser_MainServer/service_AuthService/auth-service.py", line 306, in <module>
    asyncio.run(start_service())
  File "/usr/lib/python3.12/asyncio/runners.py", line 195, in run
    return runner.run(main)
           ^^^^^^^^^^^^^^^^
  File "/usr/lib/python3.12/asyncio/runners.py", line 123, in run
    raise KeyboardInterrupt()
KeyboardInterrupt
INFO:     Started server process [95504]
INFO:     Waiting for application startup.
INFO:     Application startup complete.
INFO:     Uvicorn running on http://0.0.0.0:10000 (Press CTRL+C to quit)
INFO:     Shutting down
INFO:     Waiting for application shutdown.
INFO:     Application shutdown complete.
INFO:     Finished server process [95504]
Traceback (most recent call last):
  File "/usr/lib/python3.12/asyncio/runners.py", line 118, in run
    return self._loop.run_until_complete(task)
           ^^^^^^^^^^^^^^^^^^^^^^^^^^^^^^^^^^^
  File "/usr/lib/python3.12/asyncio/base_events.py", line 691, in run_until_complete
    return future.result()
           ^^^^^^^^^^^^^^^
asyncio.exceptions.CancelledError

During handling of the above exception, another exception occurred:

Traceback (most recent call last):
  File "/home/paarth/Neuralperk_ProxyUser_MainServer/service_AuthService/auth-service.py", line 306, in <module>
    asyncio.run(start_service())
  File "/usr/lib/python3.12/asyncio/runners.py", line 195, in run
    return runner.run(main)
           ^^^^^^^^^^^^^^^^
  File "/usr/lib/python3.12/asyncio/runners.py", line 123, in run
    raise KeyboardInterrupt()
KeyboardInterrupt
INFO:     Started server process [96827]
INFO:     Waiting for application startup.
INFO:     Application startup complete.
INFO:     Uvicorn running on http://0.0.0.0:10000 (Press CTRL+C to quit)
INFO:     Shutting down
INFO:     Waiting for application shutdown.
INFO:     Application shutdown complete.
INFO:     Finished server process [96827]
Traceback (most recent call last):
  File "/usr/lib/python3.12/asyncio/runners.py", line 118, in run
    return self._loop.run_until_complete(task)
           ^^^^^^^^^^^^^^^^^^^^^^^^^^^^^^^^^^^
  File "/usr/lib/python3.12/asyncio/base_events.py", line 691, in run_until_complete
    return future.result()
           ^^^^^^^^^^^^^^^
asyncio.exceptions.CancelledError

During handling of the above exception, another exception occurred:

Traceback (most recent call last):
  File "/home/paarth/Neuralperk_ProxyUser_MainServer/service_AuthService/auth-service.py", line 306, in <module>
    asyncio.run(start_service())
  File "/usr/lib/python3.12/asyncio/runners.py", line 195, in run
    return runner.run(main)
           ^^^^^^^^^^^^^^^^
  File "/usr/lib/python3.12/asyncio/runners.py", line 123, in run
    raise KeyboardInterrupt()
KeyboardInterrupt
INFO:     Started server process [98766]
INFO:     Waiting for application startup.
INFO:     Application startup complete.
INFO:     Uvicorn running on http://0.0.0.0:10000 (Press CTRL+C to quit)
INFO:     Shutting down
INFO:     Waiting for application shutdown.
INFO:     Application shutdown complete.
INFO:     Finished server process [98766]
Traceback (most recent call last):
  File "/usr/lib/python3.12/asyncio/runners.py", line 118, in run
    return self._loop.run_until_complete(task)
           ^^^^^^^^^^^^^^^^^^^^^^^^^^^^^^^^^^^
  File "/usr/lib/python3.12/asyncio/base_events.py", line 691, in run_until_complete
    return future.result()
           ^^^^^^^^^^^^^^^
asyncio.exceptions.CancelledError

During handling of the above exception, another exception occurred:

Traceback (most recent call last):
  File "/home/paarth/Neuralperk_ProxyUser_MainServer/service_AuthService/auth-service.py", line 306, in <module>
    asyncio.run(start_service())
  File "/usr/lib/python3.12/asyncio/runners.py", line 195, in run
    return runner.run(main)
           ^^^^^^^^^^^^^^^^
  File "/usr/lib/python3.12/asyncio/runners.py", line 123, in run
    raise KeyboardInterrupt()
KeyboardInterrupt
INFO:     Started server process [99186]
INFO:     Waiting for application startup.
INFO:     Application startup complete.
INFO:     Uvicorn running on http://0.0.0.0:10000 (Press CTRL+C to quit)
INFO:     Shutting down
INFO:     Waiting for application shutdown.
INFO:     Application shutdown complete.
INFO:     Finished server process [99186]
Traceback (most recent call last):
  File "/usr/lib/python3.12/asyncio/runners.py", line 118, in run
    return self._loop.run_until_complete(task)
           ^^^^^^^^^^^^^^^^^^^^^^^^^^^^^^^^^^^
  File "/usr/lib/python3.12/asyncio/base_events.py", line 691, in run_until_complete
    return future.result()
           ^^^^^^^^^^^^^^^
asyncio.exceptions.CancelledError

During handling of the above exception, another exception occurred:

Traceback (most recent call last):
  File "/home/paarth/Neuralperk_ProxyUser_MainServer/service_AuthService/auth-service.py", line 306, in <module>
    asyncio.run(start_service())
  File "/usr/lib/python3.12/asyncio/runners.py", line 195, in run
    return runner.run(main)
           ^^^^^^^^^^^^^^^^
  File "/usr/lib/python3.12/asyncio/runners.py", line 123, in run
    raise KeyboardInterrupt()
KeyboardInterrupt
INFO:     Started server process [99398]
INFO:     Waiting for application startup.
INFO:     Application startup complete.
INFO:     Uvicorn running on http://0.0.0.0:10000 (Press CTRL+C to quit)
INFO:     Shutting down
INFO:     Waiting for application shutdown.
INFO:     Application shutdown complete.
INFO:     Finished server process [99398]
Traceback (most recent call last):
  File "/usr/lib/python3.12/asyncio/runners.py", line 118, in run
    return self._loop.run_until_complete(task)
           ^^^^^^^^^^^^^^^^^^^^^^^^^^^^^^^^^^^
  File "/usr/lib/python3.12/asyncio/base_events.py", line 691, in run_until_complete
    return future.result()
           ^^^^^^^^^^^^^^^
asyncio.exceptions.CancelledError

During handling of the above exception, another exception occurred:

Traceback (most recent call last):
  File "/home/paarth/Neuralperk_ProxyUser_MainServer/service_AuthService/auth-service.py", line 306, in <module>
    asyncio.run(start_service())
  File "/usr/lib/python3.12/asyncio/runners.py", line 195, in run
    return runner.run(main)
           ^^^^^^^^^^^^^^^^
  File "/usr/lib/python3.12/asyncio/runners.py", line 123, in run
    raise KeyboardInterrupt()
KeyboardInterrupt
INFO:     Started server process [100622]
INFO:     Waiting for application startup.
INFO:     Application startup complete.
INFO:     Uvicorn running on http://0.0.0.0:10000 (Press CTRL+C to quit)
INFO:     Shutting down
INFO:     Waiting for application shutdown.
INFO:     Application shutdown complete.
INFO:     Finished server process [100622]
Traceback (most recent call last):
  File "/usr/lib/python3.12/asyncio/runners.py", line 118, in run
    return self._loop.run_until_complete(task)
           ^^^^^^^^^^^^^^^^^^^^^^^^^^^^^^^^^^^
  File "/usr/lib/python3.12/asyncio/base_events.py", line 691, in run_until_complete
    return future.result()
           ^^^^^^^^^^^^^^^
asyncio.exceptions.CancelledError

During handling of the above exception, another exception occurred:

Traceback (most recent call last):
  File "/home/paarth/Neuralperk_ProxyUser_MainServer/service_AuthService/auth-service.py", line 306, in <module>
    asyncio.run(start_service())
  File "/usr/lib/python3.12/asyncio/runners.py", line 195, in run
    return runner.run(main)
           ^^^^^^^^^^^^^^^^
  File "/usr/lib/python3.12/asyncio/runners.py", line 123, in run
    raise KeyboardInterrupt()
KeyboardInterrupt
INFO:     Started server process [101098]
INFO:     Waiting for application startup.
INFO:     Application startup complete.
INFO:     Uvicorn running on http://0.0.0.0:10000 (Press CTRL+C to quit)
INFO:     Shutting down
INFO:     Waiting for application shutdown.
INFO:     Application shutdown complete.
INFO:     Finished server process [101098]
Traceback (most recent call last):
  File "/usr/lib/python3.12/asyncio/runners.py", line 118, in run
    return self._loop.run_until_complete(task)
           ^^^^^^^^^^^^^^^^^^^^^^^^^^^^^^^^^^^
  File "/usr/lib/python3.12/asyncio/base_events.py", line 691, in run_until_complete
    return future.result()
           ^^^^^^^^^^^^^^^
asyncio.exceptions.CancelledError

During handling of the above exception, another exception occurred:

Traceback (most recent call last):
  File "/home/paarth/Neuralperk_ProxyUser_MainServer/service_AuthService/auth-service.py", line 306, in <module>
    asyncio.run(start_service())
  File "/usr/lib/python3.12/asyncio/runners.py", line 195, in run
    return runner.run(main)
           ^^^^^^^^^^^^^^^^
  File "/usr/lib/python3.12/asyncio/runners.py", line 123, in run
    raise KeyboardInterrupt()
KeyboardInterrupt
INFO:     Started server process [101238]
INFO:     Waiting for application startup.
INFO:     Application startup complete.
INFO:     Uvicorn running on http://0.0.0.0:10000 (Press CTRL+C to quit)
INFO:     Shutting down
INFO:     Waiting for application shutdown.
INFO:     Application shutdown complete.
INFO:     Finished server process [101238]
Traceback (most recent call last):
  File "/usr/lib/python3.12/asyncio/runners.py", line 118, in run
    return self._loop.run_until_complete(task)
           ^^^^^^^^^^^^^^^^^^^^^^^^^^^^^^^^^^^
  File "/usr/lib/python3.12/asyncio/base_events.py", line 691, in run_until_complete
    return future.result()
           ^^^^^^^^^^^^^^^
asyncio.exceptions.CancelledError

During handling of the above exception, another exception occurred:

Traceback (most recent call last):
  File "/home/paarth/Neuralperk_ProxyUser_MainServer/service_AuthService/auth-service.py", line 306, in <module>
    asyncio.run(start_service())
  File "/usr/lib/python3.12/asyncio/runners.py", line 195, in run
    return runner.run(main)
           ^^^^^^^^^^^^^^^^
  File "/usr/lib/python3.12/asyncio/runners.py", line 123, in run
    raise KeyboardInterrupt()
KeyboardInterrupt
INFO:     Started server process [101518]
INFO:     Waiting for application startup.
INFO:     Application startup complete.
INFO:     Uvicorn running on http://0.0.0.0:10000 (Press CTRL+C to quit)
